---------------------------------------
Begin Slurm Prolog: Mar-08-2024 16:46:52
Job ID:    5179092
User ID:   shardin31
Account:   gts-jw254-coda20
Job name:  Slurmshardinpowderdayrun
Partition: cpu-small
QOS:       inferno
---------------------------------------

CommandNotFoundError: Your shell has not been properly configured to use 'conda deactivate'.
To initialize your shell, run

    $ conda init <SHELL_NAME>

Currently supported shells are:
  - bash
  - fish
  - tcsh
  - xonsh
  - zsh
  - powershell

See 'conda init --help' for more information and options.

IMPORTANT: You may need to close and restart your shell after running 'conda init'.



Lmod is automatically replacing "mvapich2/2.3.6-ouywal" with "openmpi/4.1.4".

yt : [INFO     ] 2024-03-08 16:47:40,209 Global parallel computation enabled: 2 / 8
yt : [INFO     ] 2024-03-08 16:47:40,212 Global parallel computation enabled: 4 / 8
yt : [INFO     ] 2024-03-08 16:47:40,209 Global parallel computation enabled: 1 / 8
yt : [INFO     ] 2024-03-08 16:47:40,209 Global parallel computation enabled: 3 / 8
yt : [INFO     ] 2024-03-08 16:47:40,212 Global parallel computation enabled: 0 / 8
yt : [INFO     ] 2024-03-08 16:47:40,212 Global parallel computation enabled: 6 / 8
yt : [INFO     ] 2024-03-08 16:47:40,212 Global parallel computation enabled: 7 / 8
yt : [INFO     ] 2024-03-08 16:47:40,213 Global parallel computation enabled: 5 / 8
  File "analysis_pipeline.py", line 127, in <module>
    for node in tree["forest"]:
  File "/storage/home/hcoda1/7/shardin31/.conda/envs/pd_environment_3/lib/python3.8/site-packages/ytree/data_structures/tree_node.py", line 252, in __getitem__
    return self.query(key)
  File "/storage/home/hcoda1/7/shardin31/.conda/envs/pd_environment_3/lib/python3.8/site-packages/ytree/data_structures/tree_node.py", line 318, in query
    self.arbor._setup_tree(self)
  File "/storage/home/hcoda1/7/shardin31/.conda/envs/pd_environment_3/lib/python3.8/site-packages/ytree/data_structures/arbor.py", line 277, in _setup_tree
    field_data  = self._node_io._read_fields(tree_node, fields,
  File "/storage/home/hcoda1/7/shardin31/.conda/envs/pd_environment_3/lib/python3.8/site-packages/ytree/frontends/ytree/io.py", line 56, in _read_fields
    data_file.open()
  File "/storage/home/hcoda1/7/shardin31/.conda/envs/pd_environment_3/lib/python3.8/site-packages/ytree/frontends/ytree/io.py", line 34, in open
    self.analysis_fh = h5py.File(self.analysis_filename, mode="r")
  File "/storage/home/hcoda1/7/shardin31/.conda/envs/pd_environment_3/lib/python3.8/site-packages/h5py/_hl/files.py", line 567, in __init__
    fid = make_fid(name, mode, userblock_size, fapl, fcpl, swmr=swmr)
  File "/storage/home/hcoda1/7/shardin31/.conda/envs/pd_environment_3/lib/python3.8/site-packages/h5py/_hl/files.py", line 231, in make_fid
    fid = h5f.open(name, flags, fapl=fapl)
  File "h5py/_objects.pyx", line 54, in h5py._objects.with_phil.wrapper
  File "h5py/_objects.pyx", line 55, in h5py._objects.with_phil.wrapper
  File "h5py/h5f.pyx", line 106, in h5py.h5f.open
P001 yt : [ERROR    ] 2024-03-08 16:47:40,522 OSError: Unable to open file (truncated file: eof = 96, sblock->base_addr = 0, stored_eof = 2048)
  File "analysis_pipeline.py", line 127, in <module>
    for node in tree["forest"]:
  File "/storage/home/hcoda1/7/shardin31/.conda/envs/pd_environment_3/lib/python3.8/site-packages/ytree/data_structures/tree_node.py", line 252, in __getitem__
    return self.query(key)
  File "/storage/home/hcoda1/7/shardin31/.conda/envs/pd_environment_3/lib/python3.8/site-packages/ytree/data_structures/tree_node.py", line 318, in query
    self.arbor._setup_tree(self)
  File "/storage/home/hcoda1/7/shardin31/.conda/envs/pd_environment_3/lib/python3.8/site-packages/ytree/data_structures/arbor.py", line 277, in _setup_tree
    field_data  = self._node_io._read_fields(tree_node, fields,
  File "/storage/home/hcoda1/7/shardin31/.conda/envs/pd_environment_3/lib/python3.8/site-packages/ytree/frontends/ytree/io.py", line 56, in _read_fields
    data_file.open()
  File "/storage/home/hcoda1/7/shardin31/.conda/envs/pd_environment_3/lib/python3.8/site-packages/ytree/frontends/ytree/io.py", line 34, in open
  File "analysis_pipeline.py", line 127, in <module>
    for node in tree["forest"]:
  File "/storage/home/hcoda1/7/shardin31/.conda/envs/pd_environment_3/lib/python3.8/site-packages/ytree/data_structures/tree_node.py", line 252, in __getitem__
    return self.query(key)
  File "/storage/home/hcoda1/7/shardin31/.conda/envs/pd_environment_3/lib/python3.8/site-packages/ytree/data_structures/tree_node.py", line 318, in query
    self.arbor._setup_tree(self)
  File "/storage/home/hcoda1/7/shardin31/.conda/envs/pd_environment_3/lib/python3.8/site-packages/ytree/data_structures/arbor.py", line 277, in _setup_tree
    field_data  = self._node_io._read_fields(tree_node, fields,
  File "/storage/home/hcoda1/7/shardin31/.conda/envs/pd_environment_3/lib/python3.8/site-packages/ytree/frontends/ytree/io.py", line 56, in _read_fields
    data_file.open()
  File "/storage/home/hcoda1/7/shardin31/.conda/envs/pd_environment_3/lib/python3.8/site-packages/ytree/frontends/ytree/io.py", line 34, in open
    self.analysis_fh = h5py.File(self.analysis_filename, mode="r")
  File "/storage/home/hcoda1/7/shardin31/.conda/envs/pd_environment_3/lib/python3.8/site-packages/h5py/_hl/files.py", line 567, in __init__
    fid = make_fid(name, mode, userblock_size, fapl, fcpl, swmr=swmr)
  File "/storage/home/hcoda1/7/shardin31/.conda/envs/pd_environment_3/lib/python3.8/site-packages/h5py/_hl/files.py", line 231, in make_fid
    fid = h5f.open(name, flags, fapl=fapl)
  File "h5py/_objects.pyx", line 54, in h5py._objects.with_phil.wrapper
  File "h5py/_objects.pyx", line 55, in h5py._objects.with_phil.wrapper
  File "h5py/h5f.pyx", line 106, in h5py.h5f.open
P002 yt : [ERROR    ] 2024-03-08 16:47:40,522 OSError: Unable to open file (truncated file: eof = 96, sblock->base_addr = 0, stored_eof = 2048)
    self.analysis_fh = h5py.File(self.analysis_filename, mode="r")
  File "/storage/home/hcoda1/7/shardin31/.conda/envs/pd_environment_3/lib/python3.8/site-packages/h5py/_hl/files.py", line 567, in __init__
    fid = make_fid(name, mode, userblock_size, fapl, fcpl, swmr=swmr)
  File "/storage/home/hcoda1/7/shardin31/.conda/envs/pd_environment_3/lib/python3.8/site-packages/h5py/_hl/files.py", line 231, in make_fid
    fid = h5f.open(name, flags, fapl=fapl)
  File "h5py/_objects.pyx", line 54, in h5py._objects.with_phil.wrapper
  File "h5py/_objects.pyx", line 55, in h5py._objects.with_phil.wrapper
  File "h5py/h5f.pyx", line 106, in h5py.h5f.open
P005 yt : [ERROR    ] 2024-03-08 16:47:40,522 OSError: Unable to open file (truncated file: eof = 96, sblock->base_addr = 0, stored_eof = 2048)
  File "analysis_pipeline.py", line 127, in <module>
    for node in tree["forest"]:
  File "/storage/home/hcoda1/7/shardin31/.conda/envs/pd_environment_3/lib/python3.8/site-packages/ytree/data_structures/tree_node.py", line 252, in __getitem__
    return self.query(key)
  File "/storage/home/hcoda1/7/shardin31/.conda/envs/pd_environment_3/lib/python3.8/site-packages/ytree/data_structures/tree_node.py", line 318, in query
    self.arbor._setup_tree(self)
  File "/storage/home/hcoda1/7/shardin31/.conda/envs/pd_environment_3/lib/python3.8/site-packages/ytree/data_structures/arbor.py", line 277, in _setup_tree
    field_data  = self._node_io._read_fields(tree_node, fields,
  File "/storage/home/hcoda1/7/shardin31/.conda/envs/pd_environment_3/lib/python3.8/site-packages/ytree/frontends/ytree/io.py", line 56, in _read_fields
    data_file.open()
  File "/storage/home/hcoda1/7/shardin31/.conda/envs/pd_environment_3/lib/python3.8/site-packages/ytree/frontends/ytree/io.py", line 34, in open
  File "analysis_pipeline.py", line 127, in <module>
    for node in tree["forest"]:
  File "/storage/home/hcoda1/7/shardin31/.conda/envs/pd_environment_3/lib/python3.8/site-packages/ytree/data_structures/tree_node.py", line 252, in __getitem__
    return self.query(key)
  File "/storage/home/hcoda1/7/shardin31/.conda/envs/pd_environment_3/lib/python3.8/site-packages/ytree/data_structures/tree_node.py", line 318, in query
    self.arbor._setup_tree(self)
  File "/storage/home/hcoda1/7/shardin31/.conda/envs/pd_environment_3/lib/python3.8/site-packages/ytree/data_structures/arbor.py", line 277, in _setup_tree
    field_data  = self._node_io._read_fields(tree_node, fields,
  File "/storage/home/hcoda1/7/shardin31/.conda/envs/pd_environment_3/lib/python3.8/site-packages/ytree/frontends/ytree/io.py", line 56, in _read_fields
    data_file.open()
  File "/storage/home/hcoda1/7/shardin31/.conda/envs/pd_environment_3/lib/python3.8/site-packages/ytree/frontends/ytree/io.py", line 34, in open
    self.analysis_fh = h5py.File(self.analysis_filename, mode="r")
  File "/storage/home/hcoda1/7/shardin31/.conda/envs/pd_environment_3/lib/python3.8/site-packages/h5py/_hl/files.py", line 567, in __init__
    fid = make_fid(name, mode, userblock_size, fapl, fcpl, swmr=swmr)
  File "/storage/home/hcoda1/7/shardin31/.conda/envs/pd_environment_3/lib/python3.8/site-packages/h5py/_hl/files.py", line 231, in make_fid
    fid = h5f.open(name, flags, fapl=fapl)
  File "h5py/_objects.pyx", line 54, in h5py._objects.with_phil.wrapper
  File "h5py/_objects.pyx", line 55, in h5py._objects.with_phil.wrapper
  File "h5py/h5f.pyx", line 106, in h5py.h5f.open
P003 yt : [ERROR    ] 2024-03-08 16:47:40,522 OSError: Unable to open file (truncated file: eof = 96, sblock->base_addr = 0, stored_eof = 2048)
    self.analysis_fh = h5py.File(self.analysis_filename, mode="r")
  File "/storage/home/hcoda1/7/shardin31/.conda/envs/pd_environment_3/lib/python3.8/site-packages/h5py/_hl/files.py", line 567, in __init__
    fid = make_fid(name, mode, userblock_size, fapl, fcpl, swmr=swmr)
  File "/storage/home/hcoda1/7/shardin31/.conda/envs/pd_environment_3/lib/python3.8/site-packages/h5py/_hl/files.py", line 231, in make_fid
    fid = h5f.open(name, flags, fapl=fapl)
  File "h5py/_objects.pyx", line 54, in h5py._objects.with_phil.wrapper
  File "h5py/_objects.pyx", line 55, in h5py._objects.with_phil.wrapper
  File "h5py/h5f.pyx", line 106, in h5py.h5f.open
P007 yt : [ERROR    ] 2024-03-08 16:47:40,522 OSError: Unable to open file (truncated file: eof = 96, sblock->base_addr = 0, stored_eof = 2048)
  File "analysis_pipeline.py", line 127, in <module>
    for node in tree["forest"]:
  File "/storage/home/hcoda1/7/shardin31/.conda/envs/pd_environment_3/lib/python3.8/site-packages/ytree/data_structures/tree_node.py", line 252, in __getitem__
    return self.query(key)
  File "/storage/home/hcoda1/7/shardin31/.conda/envs/pd_environment_3/lib/python3.8/site-packages/ytree/data_structures/tree_node.py", line 318, in query
    self.arbor._setup_tree(self)
  File "/storage/home/hcoda1/7/shardin31/.conda/envs/pd_environment_3/lib/python3.8/site-packages/ytree/data_structures/arbor.py", line 277, in _setup_tree
    field_data  = self._node_io._read_fields(tree_node, fields,
  File "/storage/home/hcoda1/7/shardin31/.conda/envs/pd_environment_3/lib/python3.8/site-packages/ytree/frontends/ytree/io.py", line 56, in _read_fields
    data_file.open()
  File "/storage/home/hcoda1/7/shardin31/.conda/envs/pd_environment_3/lib/python3.8/site-packages/ytree/frontends/ytree/io.py", line 34, in open
    self.analysis_fh = h5py.File(self.analysis_filename, mode="r")
  File "/storage/home/hcoda1/7/shardin31/.conda/envs/pd_environment_3/lib/python3.8/site-packages/h5py/_hl/files.py", line 567, in __init__
    fid = make_fid(name, mode, userblock_size, fapl, fcpl, swmr=swmr)
  File "/storage/home/hcoda1/7/shardin31/.conda/envs/pd_environment_3/lib/python3.8/site-packages/h5py/_hl/files.py", line 231, in make_fid
    fid = h5f.open(name, flags, fapl=fapl)
  File "h5py/_objects.pyx", line 54, in h5py._objects.with_phil.wrapper
  File "h5py/_objects.pyx", line 55, in h5py._objects.with_phil.wrapper
  File "h5py/h5f.pyx", line 106, in h5py.h5f.open
P004 yt : [ERROR    ] 2024-03-08 16:47:40,522 OSError: Unable to open file (truncated file: eof = 96, sblock->base_addr = 0, stored_eof = 2048)
  File "analysis_pipeline.py", line 127, in <module>
    for node in tree["forest"]:
  File "/storage/home/hcoda1/7/shardin31/.conda/envs/pd_environment_3/lib/python3.8/site-packages/ytree/data_structures/tree_node.py", line 252, in __getitem__
    return self.query(key)
  File "/storage/home/hcoda1/7/shardin31/.conda/envs/pd_environment_3/lib/python3.8/site-packages/ytree/data_structures/tree_node.py", line 318, in query
    self.arbor._setup_tree(self)
  File "/storage/home/hcoda1/7/shardin31/.conda/envs/pd_environment_3/lib/python3.8/site-packages/ytree/data_structures/arbor.py", line 277, in _setup_tree
    field_data  = self._node_io._read_fields(tree_node, fields,
  File "/storage/home/hcoda1/7/shardin31/.conda/envs/pd_environment_3/lib/python3.8/site-packages/ytree/frontends/ytree/io.py", line 56, in _read_fields
    data_file.open()
  File "/storage/home/hcoda1/7/shardin31/.conda/envs/pd_environment_3/lib/python3.8/site-packages/ytree/frontends/ytree/io.py", line 34, in open
    self.analysis_fh = h5py.File(self.analysis_filename, mode="r")
  File "/storage/home/hcoda1/7/shardin31/.conda/envs/pd_environment_3/lib/python3.8/site-packages/h5py/_hl/files.py", line 567, in __init__
    fid = make_fid(name, mode, userblock_size, fapl, fcpl, swmr=swmr)
  File "/storage/home/hcoda1/7/shardin31/.conda/envs/pd_environment_3/lib/python3.8/site-packages/h5py/_hl/files.py", line 231, in make_fid
    fid = h5f.open(name, flags, fapl=fapl)
  File "h5py/_objects.pyx", line 54, in h5py._objects.with_phil.wrapper
  File "h5py/_objects.pyx", line 55, in h5py._objects.with_phil.wrapper
  File "h5py/h5f.pyx", line 106, in h5py.h5f.open
P006 yt : [ERROR    ] 2024-03-08 16:47:40,522 OSError: Unable to open file (truncated file: eof = 96, sblock->base_addr = 0, stored_eof = 2048)
--------------------------------------------------------------------------
MPI_ABORT was invoked on rank 2 in communicator MPI_COMM_WORLD
with errorcode 1.

NOTE: invoking MPI_ABORT causes Open MPI to kill all MPI processes.
You may or may not see output from other processes, depending on
exactly when Open MPI kills them.
--------------------------------------------------------------------------
--------------------------------------------------------------------------
MPI_ABORT was invoked on rank 3 in communicator MPI_COMM_WORLD
with errorcode 1.

NOTE: invoking MPI_ABORT causes Open MPI to kill all MPI processes.
You may or may not see output from other processes, depending on
exactly when Open MPI kills them.
--------------------------------------------------------------------------
--------------------------------------------------------------------------
MPI_ABORT was invoked on rank 4 in communicator MPI_COMM_WORLD
with errorcode 1.

NOTE: invoking MPI_ABORT causes Open MPI to kill all MPI processes.
You may or may not see output from other processes, depending on
exactly when Open MPI kills them.
--------------------------------------------------------------------------
--------------------------------------------------------------------------
MPI_ABORT was invoked on rank 5 in communicator MPI_COMM_WORLD
with errorcode 1.

NOTE: invoking MPI_ABORT causes Open MPI to kill all MPI processes.
You may or may not see output from other processes, depending on
exactly when Open MPI kills them.
--------------------------------------------------------------------------
--------------------------------------------------------------------------
MPI_ABORT was invoked on rank 7 in communicator MPI_COMM_WORLD
with errorcode 1.

NOTE: invoking MPI_ABORT causes Open MPI to kill all MPI processes.
You may or may not see output from other processes, depending on
exactly when Open MPI kills them.
--------------------------------------------------------------------------
--------------------------------------------------------------------------
MPI_ABORT was invoked on rank 6 in communicator MPI_COMM_WORLD
with errorcode 1.

NOTE: invoking MPI_ABORT causes Open MPI to kill all MPI processes.
You may or may not see output from other processes, depending on
exactly when Open MPI kills them.
--------------------------------------------------------------------------
--------------------------------------------------------------------------
MPI_ABORT was invoked on rank 1 in communicator MPI_COMM_WORLD
with errorcode 1.

NOTE: invoking MPI_ABORT causes Open MPI to kill all MPI processes.
You may or may not see output from other processes, depending on
exactly when Open MPI kills them.
--------------------------------------------------------------------------
slurmstepd: error: *** STEP 5179092.0 ON atl1-1-02-007-30-1 CANCELLED AT 2024-03-08T16:47:40 ***
srun: Job step aborted: Waiting up to 32 seconds for job step to finish.
srun: error: atl1-1-02-007-30-1: tasks 0-3: Killed
srun: error: atl1-1-02-007-30-2: tasks 4-7: Killed
---------------------------------------
Begin Slurm Epilog: Mar-08-2024 16:47:40
Job ID:        5179092
Array Job ID:  _4294967294
User ID:       shardin31
Account:       gts-jw254-coda20
Job name:      Slurmshardinpowderdayrun
Resources:     cpu=16,mem=200G,node=2
Rsrc Used:     cput=00:12:48,vmem=28100K,walltime=00:00:48,mem=5924K,energy_used=0
Partition:     cpu-small
QOS:           inferno
Nodes:         atl1-1-02-007-30-[1-2]
---------------------------------------
