---------------------------------------
Begin Slurm Prolog: Aug-29-2023 11:39:16
Job ID:    2924479
User ID:   shardin31
Account:   gts-jw254-coda20
Job name:  Slurmshardinpowderdayrun
Partition: cpu-medium
QOS:       inferno
---------------------------------------

CommandNotFoundError: Your shell has not been properly configured to use 'conda deactivate'.
To initialize your shell, run

    $ conda init <SHELL_NAME>

Currently supported shells are:
  - bash
  - fish
  - tcsh
  - xonsh
  - zsh
  - powershell

See 'conda init --help' for more information and options.

IMPORTANT: You may need to close and restart your shell after running 'conda init'.


Traceback (most recent call last):
  File "/storage/home/hcoda1/7/shardin31/.conda/envs/pd_environment_3/lib/python3.8/site-packages/h5py/_hl/files.py", line 202, in make_fid
    fid = h5f.open(name, h5f.ACC_RDWR, fapl=fapl)
  File "h5py/_objects.pyx", line 54, in h5py._objects.with_phil.wrapper
  File "h5py/_objects.pyx", line 55, in h5py._objects.with_phil.wrapper
  File "h5py/h5f.pyx", line 96, in h5py.h5f.open
OSError: Unable to open file (unable to lock file, errno = 11, error message = 'Resource temporarily unavailable')

During handling of the above exception, another exception occurred:

Traceback (most recent call last):
  File "sed_plot_0_10000.py", line 18, in <module>
    f = h5py.File("/storage/home/hcoda1/7/shardin31/p-jw254-0/Research/Powderday/powderday/final_dataset_halo_catalog.hdf5", "a")
  File "/storage/home/hcoda1/7/shardin31/.conda/envs/pd_environment_3/lib/python3.8/site-packages/h5py/_hl/files.py", line 424, in __init__
    fid = make_fid(name, mode, userblock_size,
  File "/storage/home/hcoda1/7/shardin31/.conda/envs/pd_environment_3/lib/python3.8/site-packages/h5py/_hl/files.py", line 204, in make_fid
    fid = h5f.create(name, h5f.ACC_EXCL, fapl=fapl, fcpl=fcpl)
  File "h5py/_objects.pyx", line 54, in h5py._objects.with_phil.wrapper
  File "h5py/_objects.pyx", line 55, in h5py._objects.with_phil.wrapper
  File "h5py/h5f.pyx", line 116, in h5py.h5f.create
OSError: Unable to create file (unable to open file: name = '/storage/home/hcoda1/7/shardin31/p-jw254-0/Research/Powderday/powderday/final_dataset_halo_catalog.hdf5', errno = 17, error message = 'File exists', flags = 15, o_flags = c2)
Traceback (most recent call last):
  File "/storage/home/hcoda1/7/shardin31/.conda/envs/pd_environment_3/lib/python3.8/site-packages/h5py/_hl/files.py", line 202, in make_fid
    fid = h5f.open(name, h5f.ACC_RDWR, fapl=fapl)
  File "h5py/_objects.pyx", line 54, in h5py._objects.with_phil.wrapper
  File "h5py/_objects.pyx", line 55, in h5py._objects.with_phil.wrapper
  File "h5py/h5f.pyx", line 96, in h5py.h5f.open
OSError: Unable to open file (unable to lock file, errno = 11, error message = 'Resource temporarily unavailable')

During handling of the above exception, another exception occurred:

Traceback (most recent call last):
  File "sed_plot_1_10000.py", line 18, in <module>
    f = h5py.File("/storage/home/hcoda1/7/shardin31/p-jw254-0/Research/Powderday/powderday/final_dataset_halo_catalog.hdf5", "a")
  File "/storage/home/hcoda1/7/shardin31/.conda/envs/pd_environment_3/lib/python3.8/site-packages/h5py/_hl/files.py", line 424, in __init__
    fid = make_fid(name, mode, userblock_size,
  File "/storage/home/hcoda1/7/shardin31/.conda/envs/pd_environment_3/lib/python3.8/site-packages/h5py/_hl/files.py", line 204, in make_fid
    fid = h5f.create(name, h5f.ACC_EXCL, fapl=fapl, fcpl=fcpl)
  File "h5py/_objects.pyx", line 54, in h5py._objects.with_phil.wrapper
  File "h5py/_objects.pyx", line 55, in h5py._objects.with_phil.wrapper
  File "h5py/h5f.pyx", line 116, in h5py.h5f.create
OSError: Unable to create file (unable to open file: name = '/storage/home/hcoda1/7/shardin31/p-jw254-0/Research/Powderday/powderday/final_dataset_halo_catalog.hdf5', errno = 17, error message = 'File exists', flags = 15, o_flags = c2)
Traceback (most recent call last):
  File "/storage/home/hcoda1/7/shardin31/.conda/envs/pd_environment_3/lib/python3.8/site-packages/h5py/_hl/files.py", line 202, in make_fid
    fid = h5f.open(name, h5f.ACC_RDWR, fapl=fapl)
  File "h5py/_objects.pyx", line 54, in h5py._objects.with_phil.wrapper
  File "h5py/_objects.pyx", line 55, in h5py._objects.with_phil.wrapper
  File "h5py/h5f.pyx", line 96, in h5py.h5f.open
OSError: Unable to open file (unable to lock file, errno = 11, error message = 'Resource temporarily unavailable')

During handling of the above exception, another exception occurred:

Traceback (most recent call last):
  File "sed_plot_2_10000.py", line 18, in <module>
    f = h5py.File("/storage/home/hcoda1/7/shardin31/p-jw254-0/Research/Powderday/powderday/final_dataset_halo_catalog.hdf5", "a")
  File "/storage/home/hcoda1/7/shardin31/.conda/envs/pd_environment_3/lib/python3.8/site-packages/h5py/_hl/files.py", line 424, in __init__
    fid = make_fid(name, mode, userblock_size,
  File "/storage/home/hcoda1/7/shardin31/.conda/envs/pd_environment_3/lib/python3.8/site-packages/h5py/_hl/files.py", line 204, in make_fid
    fid = h5f.create(name, h5f.ACC_EXCL, fapl=fapl, fcpl=fcpl)
  File "h5py/_objects.pyx", line 54, in h5py._objects.with_phil.wrapper
  File "h5py/_objects.pyx", line 55, in h5py._objects.with_phil.wrapper
  File "h5py/h5f.pyx", line 116, in h5py.h5f.create
OSError: Unable to create file (unable to open file: name = '/storage/home/hcoda1/7/shardin31/p-jw254-0/Research/Powderday/powderday/final_dataset_halo_catalog.hdf5', errno = 17, error message = 'File exists', flags = 15, o_flags = c2)
Traceback (most recent call last):
  File "/storage/home/hcoda1/7/shardin31/.conda/envs/pd_environment_3/lib/python3.8/site-packages/h5py/_hl/files.py", line 202, in make_fid
    fid = h5f.open(name, h5f.ACC_RDWR, fapl=fapl)
  File "h5py/_objects.pyx", line 54, in h5py._objects.with_phil.wrapper
  File "h5py/_objects.pyx", line 55, in h5py._objects.with_phil.wrapper
  File "h5py/h5f.pyx", line 96, in h5py.h5f.open
OSError: Unable to open file (unable to lock file, errno = 11, error message = 'Resource temporarily unavailable')

During handling of the above exception, another exception occurred:

Traceback (most recent call last):
  File "sed_plot_3_10000.py", line 18, in <module>
    f = h5py.File("/storage/home/hcoda1/7/shardin31/p-jw254-0/Research/Powderday/powderday/final_dataset_halo_catalog.hdf5", "a")
  File "/storage/home/hcoda1/7/shardin31/.conda/envs/pd_environment_3/lib/python3.8/site-packages/h5py/_hl/files.py", line 424, in __init__
    fid = make_fid(name, mode, userblock_size,
  File "/storage/home/hcoda1/7/shardin31/.conda/envs/pd_environment_3/lib/python3.8/site-packages/h5py/_hl/files.py", line 204, in make_fid
    fid = h5f.create(name, h5f.ACC_EXCL, fapl=fapl, fcpl=fcpl)
  File "h5py/_objects.pyx", line 54, in h5py._objects.with_phil.wrapper
  File "h5py/_objects.pyx", line 55, in h5py._objects.with_phil.wrapper
  File "h5py/h5f.pyx", line 116, in h5py.h5f.create
OSError: Unable to create file (unable to open file: name = '/storage/home/hcoda1/7/shardin31/p-jw254-0/Research/Powderday/powderday/final_dataset_halo_catalog.hdf5', errno = 17, error message = 'File exists', flags = 15, o_flags = c2)
Traceback (most recent call last):
  File "/storage/home/hcoda1/7/shardin31/.conda/envs/pd_environment_3/lib/python3.8/site-packages/h5py/_hl/files.py", line 202, in make_fid
    fid = h5f.open(name, h5f.ACC_RDWR, fapl=fapl)
  File "h5py/_objects.pyx", line 54, in h5py._objects.with_phil.wrapper
  File "h5py/_objects.pyx", line 55, in h5py._objects.with_phil.wrapper
  File "h5py/h5f.pyx", line 96, in h5py.h5f.open
OSError: Unable to open file (unable to lock file, errno = 11, error message = 'Resource temporarily unavailable')

During handling of the above exception, another exception occurred:

Traceback (most recent call last):
  File "sed_plot_4_10000.py", line 18, in <module>
    f = h5py.File("/storage/home/hcoda1/7/shardin31/p-jw254-0/Research/Powderday/powderday/final_dataset_halo_catalog.hdf5", "a")
  File "/storage/home/hcoda1/7/shardin31/.conda/envs/pd_environment_3/lib/python3.8/site-packages/h5py/_hl/files.py", line 424, in __init__
    fid = make_fid(name, mode, userblock_size,
  File "/storage/home/hcoda1/7/shardin31/.conda/envs/pd_environment_3/lib/python3.8/site-packages/h5py/_hl/files.py", line 204, in make_fid
    fid = h5f.create(name, h5f.ACC_EXCL, fapl=fapl, fcpl=fcpl)
  File "h5py/_objects.pyx", line 54, in h5py._objects.with_phil.wrapper
  File "h5py/_objects.pyx", line 55, in h5py._objects.with_phil.wrapper
  File "h5py/h5f.pyx", line 116, in h5py.h5f.create
OSError: Unable to create file (unable to open file: name = '/storage/home/hcoda1/7/shardin31/p-jw254-0/Research/Powderday/powderday/final_dataset_halo_catalog.hdf5', errno = 17, error message = 'File exists', flags = 15, o_flags = c2)
Traceback (most recent call last):
  File "/storage/home/hcoda1/7/shardin31/.conda/envs/pd_environment_3/lib/python3.8/site-packages/h5py/_hl/files.py", line 202, in make_fid
    fid = h5f.open(name, h5f.ACC_RDWR, fapl=fapl)
  File "h5py/_objects.pyx", line 54, in h5py._objects.with_phil.wrapper
  File "h5py/_objects.pyx", line 55, in h5py._objects.with_phil.wrapper
  File "h5py/h5f.pyx", line 96, in h5py.h5f.open
OSError: Unable to open file (unable to lock file, errno = 11, error message = 'Resource temporarily unavailable')

During handling of the above exception, another exception occurred:

Traceback (most recent call last):
  File "sed_plot_5_10000.py", line 18, in <module>
    f = h5py.File("/storage/home/hcoda1/7/shardin31/p-jw254-0/Research/Powderday/powderday/final_dataset_halo_catalog.hdf5", "a")
  File "/storage/home/hcoda1/7/shardin31/.conda/envs/pd_environment_3/lib/python3.8/site-packages/h5py/_hl/files.py", line 424, in __init__
    fid = make_fid(name, mode, userblock_size,
  File "/storage/home/hcoda1/7/shardin31/.conda/envs/pd_environment_3/lib/python3.8/site-packages/h5py/_hl/files.py", line 204, in make_fid
    fid = h5f.create(name, h5f.ACC_EXCL, fapl=fapl, fcpl=fcpl)
  File "h5py/_objects.pyx", line 54, in h5py._objects.with_phil.wrapper
  File "h5py/_objects.pyx", line 55, in h5py._objects.with_phil.wrapper
  File "h5py/h5f.pyx", line 116, in h5py.h5f.create
OSError: Unable to create file (unable to open file: name = '/storage/home/hcoda1/7/shardin31/p-jw254-0/Research/Powderday/powderday/final_dataset_halo_catalog.hdf5', errno = 17, error message = 'File exists', flags = 15, o_flags = c2)
Traceback (most recent call last):
  File "/storage/home/hcoda1/7/shardin31/.conda/envs/pd_environment_3/lib/python3.8/site-packages/h5py/_hl/files.py", line 202, in make_fid
    fid = h5f.open(name, h5f.ACC_RDWR, fapl=fapl)
  File "h5py/_objects.pyx", line 54, in h5py._objects.with_phil.wrapper
  File "h5py/_objects.pyx", line 55, in h5py._objects.with_phil.wrapper
  File "h5py/h5f.pyx", line 96, in h5py.h5f.open
OSError: Unable to open file (unable to lock file, errno = 11, error message = 'Resource temporarily unavailable')

During handling of the above exception, another exception occurred:

Traceback (most recent call last):
  File "sed_plot_6_10000.py", line 18, in <module>
    f = h5py.File("/storage/home/hcoda1/7/shardin31/p-jw254-0/Research/Powderday/powderday/final_dataset_halo_catalog.hdf5", "a")
  File "/storage/home/hcoda1/7/shardin31/.conda/envs/pd_environment_3/lib/python3.8/site-packages/h5py/_hl/files.py", line 424, in __init__
    fid = make_fid(name, mode, userblock_size,
  File "/storage/home/hcoda1/7/shardin31/.conda/envs/pd_environment_3/lib/python3.8/site-packages/h5py/_hl/files.py", line 204, in make_fid
    fid = h5f.create(name, h5f.ACC_EXCL, fapl=fapl, fcpl=fcpl)
  File "h5py/_objects.pyx", line 54, in h5py._objects.with_phil.wrapper
  File "h5py/_objects.pyx", line 55, in h5py._objects.with_phil.wrapper
  File "h5py/h5f.pyx", line 116, in h5py.h5f.create
OSError: Unable to create file (unable to open file: name = '/storage/home/hcoda1/7/shardin31/p-jw254-0/Research/Powderday/powderday/final_dataset_halo_catalog.hdf5', errno = 17, error message = 'File exists', flags = 15, o_flags = c2)
Traceback (most recent call last):
  File "/storage/home/hcoda1/7/shardin31/.conda/envs/pd_environment_3/lib/python3.8/site-packages/h5py/_hl/files.py", line 202, in make_fid
    fid = h5f.open(name, h5f.ACC_RDWR, fapl=fapl)
  File "h5py/_objects.pyx", line 54, in h5py._objects.with_phil.wrapper
  File "h5py/_objects.pyx", line 55, in h5py._objects.with_phil.wrapper
  File "h5py/h5f.pyx", line 96, in h5py.h5f.open
OSError: Unable to open file (unable to lock file, errno = 11, error message = 'Resource temporarily unavailable')

During handling of the above exception, another exception occurred:

Traceback (most recent call last):
  File "sed_plot_7_10000.py", line 18, in <module>
    f = h5py.File("/storage/home/hcoda1/7/shardin31/p-jw254-0/Research/Powderday/powderday/final_dataset_halo_catalog.hdf5", "a")
  File "/storage/home/hcoda1/7/shardin31/.conda/envs/pd_environment_3/lib/python3.8/site-packages/h5py/_hl/files.py", line 424, in __init__
    fid = make_fid(name, mode, userblock_size,
  File "/storage/home/hcoda1/7/shardin31/.conda/envs/pd_environment_3/lib/python3.8/site-packages/h5py/_hl/files.py", line 204, in make_fid
    fid = h5f.create(name, h5f.ACC_EXCL, fapl=fapl, fcpl=fcpl)
  File "h5py/_objects.pyx", line 54, in h5py._objects.with_phil.wrapper
  File "h5py/_objects.pyx", line 55, in h5py._objects.with_phil.wrapper
  File "h5py/h5f.pyx", line 116, in h5py.h5f.create
OSError: Unable to create file (unable to open file: name = '/storage/home/hcoda1/7/shardin31/p-jw254-0/Research/Powderday/powderday/final_dataset_halo_catalog.hdf5', errno = 17, error message = 'File exists', flags = 15, o_flags = c2)
Traceback (most recent call last):
  File "/storage/home/hcoda1/7/shardin31/.conda/envs/pd_environment_3/lib/python3.8/site-packages/h5py/_hl/files.py", line 202, in make_fid
    fid = h5f.open(name, h5f.ACC_RDWR, fapl=fapl)
  File "h5py/_objects.pyx", line 54, in h5py._objects.with_phil.wrapper
  File "h5py/_objects.pyx", line 55, in h5py._objects.with_phil.wrapper
  File "h5py/h5f.pyx", line 96, in h5py.h5f.open
OSError: Unable to open file (unable to lock file, errno = 11, error message = 'Resource temporarily unavailable')

During handling of the above exception, another exception occurred:

Traceback (most recent call last):
  File "sed_plot_8_10000.py", line 18, in <module>
    f = h5py.File("/storage/home/hcoda1/7/shardin31/p-jw254-0/Research/Powderday/powderday/final_dataset_halo_catalog.hdf5", "a")
  File "/storage/home/hcoda1/7/shardin31/.conda/envs/pd_environment_3/lib/python3.8/site-packages/h5py/_hl/files.py", line 424, in __init__
    fid = make_fid(name, mode, userblock_size,
  File "/storage/home/hcoda1/7/shardin31/.conda/envs/pd_environment_3/lib/python3.8/site-packages/h5py/_hl/files.py", line 204, in make_fid
    fid = h5f.create(name, h5f.ACC_EXCL, fapl=fapl, fcpl=fcpl)
  File "h5py/_objects.pyx", line 54, in h5py._objects.with_phil.wrapper
  File "h5py/_objects.pyx", line 55, in h5py._objects.with_phil.wrapper
  File "h5py/h5f.pyx", line 116, in h5py.h5f.create
OSError: Unable to create file (unable to open file: name = '/storage/home/hcoda1/7/shardin31/p-jw254-0/Research/Powderday/powderday/final_dataset_halo_catalog.hdf5', errno = 17, error message = 'File exists', flags = 15, o_flags = c2)
Traceback (most recent call last):
  File "/storage/home/hcoda1/7/shardin31/.conda/envs/pd_environment_3/lib/python3.8/site-packages/h5py/_hl/files.py", line 202, in make_fid
    fid = h5f.open(name, h5f.ACC_RDWR, fapl=fapl)
  File "h5py/_objects.pyx", line 54, in h5py._objects.with_phil.wrapper
  File "h5py/_objects.pyx", line 55, in h5py._objects.with_phil.wrapper
  File "h5py/h5f.pyx", line 96, in h5py.h5f.open
OSError: Unable to open file (unable to lock file, errno = 11, error message = 'Resource temporarily unavailable')

During handling of the above exception, another exception occurred:

Traceback (most recent call last):
  File "sed_plot_9_10000.py", line 18, in <module>
    f = h5py.File("/storage/home/hcoda1/7/shardin31/p-jw254-0/Research/Powderday/powderday/final_dataset_halo_catalog.hdf5", "a")
  File "/storage/home/hcoda1/7/shardin31/.conda/envs/pd_environment_3/lib/python3.8/site-packages/h5py/_hl/files.py", line 424, in __init__
    fid = make_fid(name, mode, userblock_size,
  File "/storage/home/hcoda1/7/shardin31/.conda/envs/pd_environment_3/lib/python3.8/site-packages/h5py/_hl/files.py", line 204, in make_fid
    fid = h5f.create(name, h5f.ACC_EXCL, fapl=fapl, fcpl=fcpl)
  File "h5py/_objects.pyx", line 54, in h5py._objects.with_phil.wrapper
  File "h5py/_objects.pyx", line 55, in h5py._objects.with_phil.wrapper
  File "h5py/h5f.pyx", line 116, in h5py.h5f.create
OSError: Unable to create file (unable to open file: name = '/storage/home/hcoda1/7/shardin31/p-jw254-0/Research/Powderday/powderday/final_dataset_halo_catalog.hdf5', errno = 17, error message = 'File exists', flags = 15, o_flags = c2)
Traceback (most recent call last):
  File "/storage/home/hcoda1/7/shardin31/.conda/envs/pd_environment_3/lib/python3.8/site-packages/h5py/_hl/files.py", line 202, in make_fid
    fid = h5f.open(name, h5f.ACC_RDWR, fapl=fapl)
  File "h5py/_objects.pyx", line 54, in h5py._objects.with_phil.wrapper
  File "h5py/_objects.pyx", line 55, in h5py._objects.with_phil.wrapper
  File "h5py/h5f.pyx", line 96, in h5py.h5f.open
OSError: Unable to open file (unable to lock file, errno = 11, error message = 'Resource temporarily unavailable')

During handling of the above exception, another exception occurred:

Traceback (most recent call last):
  File "sed_plot_10_10000.py", line 18, in <module>
    f = h5py.File("/storage/home/hcoda1/7/shardin31/p-jw254-0/Research/Powderday/powderday/final_dataset_halo_catalog.hdf5", "a")
  File "/storage/home/hcoda1/7/shardin31/.conda/envs/pd_environment_3/lib/python3.8/site-packages/h5py/_hl/files.py", line 424, in __init__
    fid = make_fid(name, mode, userblock_size,
  File "/storage/home/hcoda1/7/shardin31/.conda/envs/pd_environment_3/lib/python3.8/site-packages/h5py/_hl/files.py", line 204, in make_fid
    fid = h5f.create(name, h5f.ACC_EXCL, fapl=fapl, fcpl=fcpl)
  File "h5py/_objects.pyx", line 54, in h5py._objects.with_phil.wrapper
  File "h5py/_objects.pyx", line 55, in h5py._objects.with_phil.wrapper
  File "h5py/h5f.pyx", line 116, in h5py.h5f.create
OSError: Unable to create file (unable to open file: name = '/storage/home/hcoda1/7/shardin31/p-jw254-0/Research/Powderday/powderday/final_dataset_halo_catalog.hdf5', errno = 17, error message = 'File exists', flags = 15, o_flags = c2)
Traceback (most recent call last):
  File "/storage/home/hcoda1/7/shardin31/.conda/envs/pd_environment_3/lib/python3.8/site-packages/h5py/_hl/files.py", line 202, in make_fid
    fid = h5f.open(name, h5f.ACC_RDWR, fapl=fapl)
  File "h5py/_objects.pyx", line 54, in h5py._objects.with_phil.wrapper
  File "h5py/_objects.pyx", line 55, in h5py._objects.with_phil.wrapper
  File "h5py/h5f.pyx", line 96, in h5py.h5f.open
OSError: Unable to open file (unable to lock file, errno = 11, error message = 'Resource temporarily unavailable')

During handling of the above exception, another exception occurred:

Traceback (most recent call last):
  File "sed_plot_0_100000.py", line 18, in <module>
    f = h5py.File("/storage/home/hcoda1/7/shardin31/p-jw254-0/Research/Powderday/powderday/final_dataset_halo_catalog.hdf5", "a")
  File "/storage/home/hcoda1/7/shardin31/.conda/envs/pd_environment_3/lib/python3.8/site-packages/h5py/_hl/files.py", line 424, in __init__
    fid = make_fid(name, mode, userblock_size,
  File "/storage/home/hcoda1/7/shardin31/.conda/envs/pd_environment_3/lib/python3.8/site-packages/h5py/_hl/files.py", line 204, in make_fid
    fid = h5f.create(name, h5f.ACC_EXCL, fapl=fapl, fcpl=fcpl)
  File "h5py/_objects.pyx", line 54, in h5py._objects.with_phil.wrapper
  File "h5py/_objects.pyx", line 55, in h5py._objects.with_phil.wrapper
  File "h5py/h5f.pyx", line 116, in h5py.h5f.create
OSError: Unable to create file (unable to open file: name = '/storage/home/hcoda1/7/shardin31/p-jw254-0/Research/Powderday/powderday/final_dataset_halo_catalog.hdf5', errno = 17, error message = 'File exists', flags = 15, o_flags = c2)
Traceback (most recent call last):
  File "/storage/home/hcoda1/7/shardin31/.conda/envs/pd_environment_3/lib/python3.8/site-packages/h5py/_hl/files.py", line 202, in make_fid
    fid = h5f.open(name, h5f.ACC_RDWR, fapl=fapl)
  File "h5py/_objects.pyx", line 54, in h5py._objects.with_phil.wrapper
  File "h5py/_objects.pyx", line 55, in h5py._objects.with_phil.wrapper
  File "h5py/h5f.pyx", line 96, in h5py.h5f.open
OSError: Unable to open file (unable to lock file, errno = 11, error message = 'Resource temporarily unavailable')

During handling of the above exception, another exception occurred:

Traceback (most recent call last):
  File "sed_plot_1_100000.py", line 18, in <module>
    f = h5py.File("/storage/home/hcoda1/7/shardin31/p-jw254-0/Research/Powderday/powderday/final_dataset_halo_catalog.hdf5", "a")
  File "/storage/home/hcoda1/7/shardin31/.conda/envs/pd_environment_3/lib/python3.8/site-packages/h5py/_hl/files.py", line 424, in __init__
    fid = make_fid(name, mode, userblock_size,
  File "/storage/home/hcoda1/7/shardin31/.conda/envs/pd_environment_3/lib/python3.8/site-packages/h5py/_hl/files.py", line 204, in make_fid
    fid = h5f.create(name, h5f.ACC_EXCL, fapl=fapl, fcpl=fcpl)
  File "h5py/_objects.pyx", line 54, in h5py._objects.with_phil.wrapper
  File "h5py/_objects.pyx", line 55, in h5py._objects.with_phil.wrapper
  File "h5py/h5f.pyx", line 116, in h5py.h5f.create
OSError: Unable to create file (unable to open file: name = '/storage/home/hcoda1/7/shardin31/p-jw254-0/Research/Powderday/powderday/final_dataset_halo_catalog.hdf5', errno = 17, error message = 'File exists', flags = 15, o_flags = c2)
Traceback (most recent call last):
  File "/storage/home/hcoda1/7/shardin31/.conda/envs/pd_environment_3/lib/python3.8/site-packages/h5py/_hl/files.py", line 202, in make_fid
    fid = h5f.open(name, h5f.ACC_RDWR, fapl=fapl)
  File "h5py/_objects.pyx", line 54, in h5py._objects.with_phil.wrapper
  File "h5py/_objects.pyx", line 55, in h5py._objects.with_phil.wrapper
  File "h5py/h5f.pyx", line 96, in h5py.h5f.open
OSError: Unable to open file (unable to lock file, errno = 11, error message = 'Resource temporarily unavailable')

During handling of the above exception, another exception occurred:

Traceback (most recent call last):
  File "sed_plot_2_100000.py", line 18, in <module>
    f = h5py.File("/storage/home/hcoda1/7/shardin31/p-jw254-0/Research/Powderday/powderday/final_dataset_halo_catalog.hdf5", "a")
  File "/storage/home/hcoda1/7/shardin31/.conda/envs/pd_environment_3/lib/python3.8/site-packages/h5py/_hl/files.py", line 424, in __init__
    fid = make_fid(name, mode, userblock_size,
  File "/storage/home/hcoda1/7/shardin31/.conda/envs/pd_environment_3/lib/python3.8/site-packages/h5py/_hl/files.py", line 204, in make_fid
    fid = h5f.create(name, h5f.ACC_EXCL, fapl=fapl, fcpl=fcpl)
  File "h5py/_objects.pyx", line 54, in h5py._objects.with_phil.wrapper
  File "h5py/_objects.pyx", line 55, in h5py._objects.with_phil.wrapper
  File "h5py/h5f.pyx", line 116, in h5py.h5f.create
OSError: Unable to create file (unable to open file: name = '/storage/home/hcoda1/7/shardin31/p-jw254-0/Research/Powderday/powderday/final_dataset_halo_catalog.hdf5', errno = 17, error message = 'File exists', flags = 15, o_flags = c2)
Traceback (most recent call last):
  File "/storage/home/hcoda1/7/shardin31/.conda/envs/pd_environment_3/lib/python3.8/site-packages/h5py/_hl/files.py", line 202, in make_fid
    fid = h5f.open(name, h5f.ACC_RDWR, fapl=fapl)
  File "h5py/_objects.pyx", line 54, in h5py._objects.with_phil.wrapper
  File "h5py/_objects.pyx", line 55, in h5py._objects.with_phil.wrapper
  File "h5py/h5f.pyx", line 96, in h5py.h5f.open
OSError: Unable to open file (unable to lock file, errno = 11, error message = 'Resource temporarily unavailable')

During handling of the above exception, another exception occurred:

Traceback (most recent call last):
  File "sed_plot_3_100000.py", line 18, in <module>
    f = h5py.File("/storage/home/hcoda1/7/shardin31/p-jw254-0/Research/Powderday/powderday/final_dataset_halo_catalog.hdf5", "a")
  File "/storage/home/hcoda1/7/shardin31/.conda/envs/pd_environment_3/lib/python3.8/site-packages/h5py/_hl/files.py", line 424, in __init__
    fid = make_fid(name, mode, userblock_size,
  File "/storage/home/hcoda1/7/shardin31/.conda/envs/pd_environment_3/lib/python3.8/site-packages/h5py/_hl/files.py", line 204, in make_fid
    fid = h5f.create(name, h5f.ACC_EXCL, fapl=fapl, fcpl=fcpl)
  File "h5py/_objects.pyx", line 54, in h5py._objects.with_phil.wrapper
  File "h5py/_objects.pyx", line 55, in h5py._objects.with_phil.wrapper
  File "h5py/h5f.pyx", line 116, in h5py.h5f.create
OSError: Unable to create file (unable to open file: name = '/storage/home/hcoda1/7/shardin31/p-jw254-0/Research/Powderday/powderday/final_dataset_halo_catalog.hdf5', errno = 17, error message = 'File exists', flags = 15, o_flags = c2)
Traceback (most recent call last):
  File "/storage/home/hcoda1/7/shardin31/.conda/envs/pd_environment_3/lib/python3.8/site-packages/h5py/_hl/files.py", line 202, in make_fid
    fid = h5f.open(name, h5f.ACC_RDWR, fapl=fapl)
  File "h5py/_objects.pyx", line 54, in h5py._objects.with_phil.wrapper
  File "h5py/_objects.pyx", line 55, in h5py._objects.with_phil.wrapper
  File "h5py/h5f.pyx", line 96, in h5py.h5f.open
OSError: Unable to open file (unable to lock file, errno = 11, error message = 'Resource temporarily unavailable')

During handling of the above exception, another exception occurred:

Traceback (most recent call last):
  File "sed_plot_4_100000.py", line 18, in <module>
    f = h5py.File("/storage/home/hcoda1/7/shardin31/p-jw254-0/Research/Powderday/powderday/final_dataset_halo_catalog.hdf5", "a")
  File "/storage/home/hcoda1/7/shardin31/.conda/envs/pd_environment_3/lib/python3.8/site-packages/h5py/_hl/files.py", line 424, in __init__
    fid = make_fid(name, mode, userblock_size,
  File "/storage/home/hcoda1/7/shardin31/.conda/envs/pd_environment_3/lib/python3.8/site-packages/h5py/_hl/files.py", line 204, in make_fid
    fid = h5f.create(name, h5f.ACC_EXCL, fapl=fapl, fcpl=fcpl)
  File "h5py/_objects.pyx", line 54, in h5py._objects.with_phil.wrapper
  File "h5py/_objects.pyx", line 55, in h5py._objects.with_phil.wrapper
  File "h5py/h5f.pyx", line 116, in h5py.h5f.create
OSError: Unable to create file (unable to open file: name = '/storage/home/hcoda1/7/shardin31/p-jw254-0/Research/Powderday/powderday/final_dataset_halo_catalog.hdf5', errno = 17, error message = 'File exists', flags = 15, o_flags = c2)
Traceback (most recent call last):
  File "/storage/home/hcoda1/7/shardin31/.conda/envs/pd_environment_3/lib/python3.8/site-packages/h5py/_hl/files.py", line 202, in make_fid
    fid = h5f.open(name, h5f.ACC_RDWR, fapl=fapl)
  File "h5py/_objects.pyx", line 54, in h5py._objects.with_phil.wrapper
  File "h5py/_objects.pyx", line 55, in h5py._objects.with_phil.wrapper
  File "h5py/h5f.pyx", line 96, in h5py.h5f.open
OSError: Unable to open file (unable to lock file, errno = 11, error message = 'Resource temporarily unavailable')

During handling of the above exception, another exception occurred:

Traceback (most recent call last):
  File "sed_plot_5_100000.py", line 18, in <module>
    f = h5py.File("/storage/home/hcoda1/7/shardin31/p-jw254-0/Research/Powderday/powderday/final_dataset_halo_catalog.hdf5", "a")
  File "/storage/home/hcoda1/7/shardin31/.conda/envs/pd_environment_3/lib/python3.8/site-packages/h5py/_hl/files.py", line 424, in __init__
    fid = make_fid(name, mode, userblock_size,
  File "/storage/home/hcoda1/7/shardin31/.conda/envs/pd_environment_3/lib/python3.8/site-packages/h5py/_hl/files.py", line 204, in make_fid
    fid = h5f.create(name, h5f.ACC_EXCL, fapl=fapl, fcpl=fcpl)
  File "h5py/_objects.pyx", line 54, in h5py._objects.with_phil.wrapper
  File "h5py/_objects.pyx", line 55, in h5py._objects.with_phil.wrapper
  File "h5py/h5f.pyx", line 116, in h5py.h5f.create
OSError: Unable to create file (unable to open file: name = '/storage/home/hcoda1/7/shardin31/p-jw254-0/Research/Powderday/powderday/final_dataset_halo_catalog.hdf5', errno = 17, error message = 'File exists', flags = 15, o_flags = c2)
Traceback (most recent call last):
  File "/storage/home/hcoda1/7/shardin31/.conda/envs/pd_environment_3/lib/python3.8/site-packages/h5py/_hl/files.py", line 202, in make_fid
    fid = h5f.open(name, h5f.ACC_RDWR, fapl=fapl)
  File "h5py/_objects.pyx", line 54, in h5py._objects.with_phil.wrapper
  File "h5py/_objects.pyx", line 55, in h5py._objects.with_phil.wrapper
  File "h5py/h5f.pyx", line 96, in h5py.h5f.open
OSError: Unable to open file (unable to lock file, errno = 11, error message = 'Resource temporarily unavailable')

During handling of the above exception, another exception occurred:

Traceback (most recent call last):
  File "sed_plot_6_100000.py", line 18, in <module>
    f = h5py.File("/storage/home/hcoda1/7/shardin31/p-jw254-0/Research/Powderday/powderday/final_dataset_halo_catalog.hdf5", "a")
  File "/storage/home/hcoda1/7/shardin31/.conda/envs/pd_environment_3/lib/python3.8/site-packages/h5py/_hl/files.py", line 424, in __init__
    fid = make_fid(name, mode, userblock_size,
  File "/storage/home/hcoda1/7/shardin31/.conda/envs/pd_environment_3/lib/python3.8/site-packages/h5py/_hl/files.py", line 204, in make_fid
    fid = h5f.create(name, h5f.ACC_EXCL, fapl=fapl, fcpl=fcpl)
  File "h5py/_objects.pyx", line 54, in h5py._objects.with_phil.wrapper
  File "h5py/_objects.pyx", line 55, in h5py._objects.with_phil.wrapper
  File "h5py/h5f.pyx", line 116, in h5py.h5f.create
OSError: Unable to create file (unable to open file: name = '/storage/home/hcoda1/7/shardin31/p-jw254-0/Research/Powderday/powderday/final_dataset_halo_catalog.hdf5', errno = 17, error message = 'File exists', flags = 15, o_flags = c2)
Traceback (most recent call last):
  File "/storage/home/hcoda1/7/shardin31/.conda/envs/pd_environment_3/lib/python3.8/site-packages/h5py/_hl/files.py", line 202, in make_fid
    fid = h5f.open(name, h5f.ACC_RDWR, fapl=fapl)
  File "h5py/_objects.pyx", line 54, in h5py._objects.with_phil.wrapper
  File "h5py/_objects.pyx", line 55, in h5py._objects.with_phil.wrapper
  File "h5py/h5f.pyx", line 96, in h5py.h5f.open
OSError: Unable to open file (unable to lock file, errno = 11, error message = 'Resource temporarily unavailable')

During handling of the above exception, another exception occurred:

Traceback (most recent call last):
  File "sed_plot_7_100000.py", line 18, in <module>
    f = h5py.File("/storage/home/hcoda1/7/shardin31/p-jw254-0/Research/Powderday/powderday/final_dataset_halo_catalog.hdf5", "a")
  File "/storage/home/hcoda1/7/shardin31/.conda/envs/pd_environment_3/lib/python3.8/site-packages/h5py/_hl/files.py", line 424, in __init__
    fid = make_fid(name, mode, userblock_size,
  File "/storage/home/hcoda1/7/shardin31/.conda/envs/pd_environment_3/lib/python3.8/site-packages/h5py/_hl/files.py", line 204, in make_fid
    fid = h5f.create(name, h5f.ACC_EXCL, fapl=fapl, fcpl=fcpl)
  File "h5py/_objects.pyx", line 54, in h5py._objects.with_phil.wrapper
  File "h5py/_objects.pyx", line 55, in h5py._objects.with_phil.wrapper
  File "h5py/h5f.pyx", line 116, in h5py.h5f.create
OSError: Unable to create file (unable to open file: name = '/storage/home/hcoda1/7/shardin31/p-jw254-0/Research/Powderday/powderday/final_dataset_halo_catalog.hdf5', errno = 17, error message = 'File exists', flags = 15, o_flags = c2)
Traceback (most recent call last):
  File "/storage/home/hcoda1/7/shardin31/.conda/envs/pd_environment_3/lib/python3.8/site-packages/h5py/_hl/files.py", line 202, in make_fid
    fid = h5f.open(name, h5f.ACC_RDWR, fapl=fapl)
  File "h5py/_objects.pyx", line 54, in h5py._objects.with_phil.wrapper
  File "h5py/_objects.pyx", line 55, in h5py._objects.with_phil.wrapper
  File "h5py/h5f.pyx", line 96, in h5py.h5f.open
OSError: Unable to open file (unable to lock file, errno = 11, error message = 'Resource temporarily unavailable')

During handling of the above exception, another exception occurred:

Traceback (most recent call last):
  File "sed_plot_8_100000.py", line 18, in <module>
    f = h5py.File("/storage/home/hcoda1/7/shardin31/p-jw254-0/Research/Powderday/powderday/final_dataset_halo_catalog.hdf5", "a")
  File "/storage/home/hcoda1/7/shardin31/.conda/envs/pd_environment_3/lib/python3.8/site-packages/h5py/_hl/files.py", line 424, in __init__
    fid = make_fid(name, mode, userblock_size,
  File "/storage/home/hcoda1/7/shardin31/.conda/envs/pd_environment_3/lib/python3.8/site-packages/h5py/_hl/files.py", line 204, in make_fid
    fid = h5f.create(name, h5f.ACC_EXCL, fapl=fapl, fcpl=fcpl)
  File "h5py/_objects.pyx", line 54, in h5py._objects.with_phil.wrapper
  File "h5py/_objects.pyx", line 55, in h5py._objects.with_phil.wrapper
  File "h5py/h5f.pyx", line 116, in h5py.h5f.create
OSError: Unable to create file (unable to open file: name = '/storage/home/hcoda1/7/shardin31/p-jw254-0/Research/Powderday/powderday/final_dataset_halo_catalog.hdf5', errno = 17, error message = 'File exists', flags = 15, o_flags = c2)
Traceback (most recent call last):
  File "/storage/home/hcoda1/7/shardin31/.conda/envs/pd_environment_3/lib/python3.8/site-packages/h5py/_hl/files.py", line 202, in make_fid
    fid = h5f.open(name, h5f.ACC_RDWR, fapl=fapl)
  File "h5py/_objects.pyx", line 54, in h5py._objects.with_phil.wrapper
  File "h5py/_objects.pyx", line 55, in h5py._objects.with_phil.wrapper
  File "h5py/h5f.pyx", line 96, in h5py.h5f.open
OSError: Unable to open file (unable to lock file, errno = 11, error message = 'Resource temporarily unavailable')

During handling of the above exception, another exception occurred:

Traceback (most recent call last):
  File "sed_plot_9_100000.py", line 18, in <module>
    f = h5py.File("/storage/home/hcoda1/7/shardin31/p-jw254-0/Research/Powderday/powderday/final_dataset_halo_catalog.hdf5", "a")
  File "/storage/home/hcoda1/7/shardin31/.conda/envs/pd_environment_3/lib/python3.8/site-packages/h5py/_hl/files.py", line 424, in __init__
    fid = make_fid(name, mode, userblock_size,
  File "/storage/home/hcoda1/7/shardin31/.conda/envs/pd_environment_3/lib/python3.8/site-packages/h5py/_hl/files.py", line 204, in make_fid
    fid = h5f.create(name, h5f.ACC_EXCL, fapl=fapl, fcpl=fcpl)
  File "h5py/_objects.pyx", line 54, in h5py._objects.with_phil.wrapper
  File "h5py/_objects.pyx", line 55, in h5py._objects.with_phil.wrapper
  File "h5py/h5f.pyx", line 116, in h5py.h5f.create
OSError: Unable to create file (unable to open file: name = '/storage/home/hcoda1/7/shardin31/p-jw254-0/Research/Powderday/powderday/final_dataset_halo_catalog.hdf5', errno = 17, error message = 'File exists', flags = 15, o_flags = c2)
Traceback (most recent call last):
  File "/storage/home/hcoda1/7/shardin31/.conda/envs/pd_environment_3/lib/python3.8/site-packages/h5py/_hl/files.py", line 202, in make_fid
    fid = h5f.open(name, h5f.ACC_RDWR, fapl=fapl)
  File "h5py/_objects.pyx", line 54, in h5py._objects.with_phil.wrapper
  File "h5py/_objects.pyx", line 55, in h5py._objects.with_phil.wrapper
  File "h5py/h5f.pyx", line 96, in h5py.h5f.open
OSError: Unable to open file (unable to lock file, errno = 11, error message = 'Resource temporarily unavailable')

During handling of the above exception, another exception occurred:

Traceback (most recent call last):
  File "sed_plot_10_100000.py", line 18, in <module>
    f = h5py.File("/storage/home/hcoda1/7/shardin31/p-jw254-0/Research/Powderday/powderday/final_dataset_halo_catalog.hdf5", "a")
  File "/storage/home/hcoda1/7/shardin31/.conda/envs/pd_environment_3/lib/python3.8/site-packages/h5py/_hl/files.py", line 424, in __init__
    fid = make_fid(name, mode, userblock_size,
  File "/storage/home/hcoda1/7/shardin31/.conda/envs/pd_environment_3/lib/python3.8/site-packages/h5py/_hl/files.py", line 204, in make_fid
    fid = h5f.create(name, h5f.ACC_EXCL, fapl=fapl, fcpl=fcpl)
  File "h5py/_objects.pyx", line 54, in h5py._objects.with_phil.wrapper
  File "h5py/_objects.pyx", line 55, in h5py._objects.with_phil.wrapper
  File "h5py/h5f.pyx", line 116, in h5py.h5f.create
OSError: Unable to create file (unable to open file: name = '/storage/home/hcoda1/7/shardin31/p-jw254-0/Research/Powderday/powderday/final_dataset_halo_catalog.hdf5', errno = 17, error message = 'File exists', flags = 15, o_flags = c2)
---------------------------------------
Begin Slurm Epilog: Aug-29-2023 11:40:32
Job ID:        2924479
Array Job ID:  _4294967294
User ID:       shardin31
Account:       gts-jw254-coda20
Job name:      Slurmshardinpowderdayrun
Resources:     cpu=32,mem=720G,node=2
Rsrc Used:     cput=00:42:08,vmem=178084K,walltime=00:01:19,mem=84488K,energy_used=0
Partition:     cpu-medium
QOS:           inferno
Nodes:         atl1-1-01-005-29-[1-2]
---------------------------------------
